Workbook
Name \\vv: #N/A
Name \0: #REF!
Name \0: #REF!
Name \0: #REF!
Name \1: #REF!
Name \1: #REF!
Name \1: #REF!
Name \a: #N/A
Name \b: #N/A
Name \c: #N/A
Name \d: #N/A
Name \ddd: #N/A
Name \e: #N/A
Name \f: #N/A
Name \g: #N/A
Name \h: #N/A
Name \i: #N/A
Name \j: #N/A
Name \K: #REF!
Name \K: #REF!
Name \K: #REF!
Name \l: #N/A
Name \m: #N/A
Name \n: #N/A
Name \o: #N/A
Name \p: #N/A
Name \pp: #N/A
Name \Q: #REF!
Name \Q: #REF!
Name \Q: #REF!
Name \qq: [2]Conver!#REF!
Name \qq: [2]Conver!#REF!
Name \qq: [2]Conver!#REF!
Name \r: #N/A
Name \s: #N/A
Name \t: #N/A
Name \u: #N/A
Name \v: #N/A
Name \vv: #N/A
Name \w: #N/A
Name \we: #N/A
Name \ww: #N/A
Name \wwe: #N/A
Name \x: '[3]XE-CPL'!#REF!
Name \x: '[3]XE-CPL'!#REF!
Name \x: '[3]XE-CPL'!#REF!
Name \x1: '[3]XE-CPL'!#REF!
Name \x1: '[3]XE-CPL'!#REF!
Name \x1: '[3]XE-CPL'!#REF!
Name \z: #N/A
Name \zz: #N/A
Name ______DAT1: [4]RA!#REF!
Name ______DAT1: [4]RA!#REF!
Name ______DAT1: [4]RA!#REF!
Name ______DAT2: [4]RA!#REF!
Name ______DAT2: [4]RA!#REF!
Name ______DAT2: [4]RA!#REF!
Name ______DAT3: [4]RA!#REF!
Name ______DAT3: [4]RA!#REF!
Name ______DAT6: [4]RA!#REF!

Sheet CAPEX SUMMARY
A1: AGRIAUTO STAMPING COMPANY PVT LIMITED
A2: REPAIR & MAINTENANCE BUDGET
A3: 2026-27
A5: Sr. # | B5: DESCRIPTION OF ITEM | C5: QTY. | D5: NEW USED/REFUR | E5: IMPORT / LOCAL | F5: FY 2026-27 (Rs.) | WZI5: Budget Utilization | WZJ5: Remaining budget | WZK5: Utilization %
A7: A | B7: CARRY FORWARD PROJECTS / PROJECTS | E7: Local | F7: ='CAPEX Detail'!H13 -> 27958050
A9: B | B9: PROPOSED CAPEX | E9: Import | F9: ='CAPEX Detail'!H49 -> 3.1072048e+08
A11: C | B11: Vehicles | E11: Import | F11: ='CAPEX Detail'!H62 -> 41430500
B14: Grand Total | D14: Total (A+B) | F14: =F7+F9+F11 -> 3.8010903e+08

Sheet CAPEX Detail
A1: AGRIAUTO STAMPING COMPANY
A2: CAPITAL EXPENDITURE
A3: BUDGET - 2026-27
A5: Sr.# | B5: DESCRIPTION OF ITEM | C5: CLASSIFICATION | D5: QTY. | E5: SOURCE/ ORIGIN | F5: DATE | G5: Category | H5: Rs. | I5: JUSTIFICATIONS
H6: AMOUNT
L7: 2000005372
A8: A | B8: CARRY FORWARD PROJECTS / PROJECTS
A9: A-1 | B9: DEVELOPMENT PROJECTS
A10: A- | B10: CF Deck Extension work | C10: New | D10: Var | E10: Local | F10: Sep'26 | H10: 17958050 | I10: Work under progress.
B11: 02 Welding Guns For YXO Project | C11: New | F11: Nov'26 | H11: 10000000 | L11: =1185121.2*1.8 -> 2133218.2
E13: TOTAL- >>>>>> A | H13: =SUM(H10:H12) -> 27958050
A15: B | B15: PROPOSED CAPEX
A16: B-1 | B16: Upgradation Works/Projects
A17: A- | B17: 200KW Solar energy generation system with BESS | C17: New | D17: 1 | E17: Import/Local | F17: 46419 | H17: 20000000 | I17: Panels will be installed on Warehouse building at ASC after extension along with batteries | J17: Quotation check with weight and clearance
A18: B- | B18: New Blanking Pess ( 500T - Used condition) | C18: Refurbish | D18: 1 | E18: Import/Local | F18: 46413 | H18: 100000000 | I18: Quotation awaited from Horiuchi san. Estimated price added | J18: Quotation check with weight and clearance
A19: C- | B19: CNC vertical Machining Center (1500x800)mm | C19: New | D19: 1 | E19: Import/Local | F19: Dec'26 | H19: =(146600*295*1.1)+5000000+2000000 -> 54571700 | I19: 146,600*280 + 10% Clearance & Duty + 1M Machine inspection + 1M Installation + 5M Foundation
A20: D- | B20: Shearing Machine | C20: New | D20: 1 | E20: Import/Local | F20: Nov'26 | H20: =50000*295*1.2 -> 17700000 | I20: 50000*280 + 5% Clearance & Duty + Installation Cost
B21: Welding Robot (Automation) | C21: New | D21: 1 | E21: Import/Local | F21: Dec'26 | H21: 20000000 | I21: Productivity Improvement for Yaris Line
A22: E- | B22: Auto Die Cart | C22: New | D22: 1 | E22: Import/Local | F22: Dec'26 | H22: 5000000 | I22: For New die area, replaced from manual to auto
A23: F- | B23: Racks for Extended C.C Warehouse Building - 36 No. Racks | H23: 0 | I23: RM
E24: TOTAL- >>>>>> B-1 | H24: =SUM(H17:H23) -> 217271700
A26: B-2 | B26: Misc Department
A27: A- | B27: Portable Inverter Tig+Stick welding Machine (DM&Fab) | C27: New | D27: 2 | E27: Local | F27: Dec'26 | H27: =546000+975000 -> 1521000
A28: B- | B28: AC For GL & Asakai Room | C28: Replacement | D28: 2 | E28: Local | F28: Sep'26 | H28: 1000000
A29: C- | B29: Suzuki Carry | C29: New | D29: 1 | E29: Local | F29: Dec'26
A30: D- | B30: Truck & Deck for Supplies of new upcoming projects (YXO, W&D) | C30: New | D30: 1 | E30: Local | F30: Oct'26 | H30: 11200000 | I30: 9.9M for Truck + 1.1M for Deck
A31: E- | B31: Fork Lifter 2/3.5 Ton Capacity (EV) | C31: Refurbish | D31: 1 | E31: Local | F31: Nov'26 | H31: =5000000*1.1 -> 5500000 | I31: Estimated. Quotation awaited from Horiuchi san
A32: F- | B32: Battery Stacker 2 Ton Capacity | C32: Replacement | D32: 2 | E32: Local | F32: Dec'26 | H32: 16905900 | I32: (23500x327)*10& Duty & Clearance
A33: G | B33: Air Dryer For C.C Compressor | C33: New | D33: 1 | E33: Local | F33: Dec'26 | H33: 1746000 | I33: (4643*327)+15% Freight Duty& Clearance
A34: I- | B34: QLED for Asakai Room/QC/SCM (Digitization) | C34: New | D34: 3 | E34: Local | F34: Sep'26 | H34: =240000+340000+370000 -> 950000
E36: TOTAL- >>>>>> B-3 | H36: =SUM(H27:H34) -> 38822900
A38: B-3 | B38: IT - Server & Accessories
A39: A- | B39: Computer Sets | C39: Replacement | D39: 10 | E39: Local | H39: 6705800
A40: B- | B40: Desktop PC / Laptops | D40: 6 | E40: Local | H40: 4000000
A41: C- | B41: Laptops | D41: 6 | E41: Local | H41: 2700000
A42: D- | B42: Projector | D42: 1 | E42: Local | H42: 305084.74
A43: E- | B43: Network Switch | D43: 2 | E43: Local | H43: 790000
A44: F- | B44: HP Laser Printer | C44: Replacement | D44: 1 | E44: Local | H44: 125000
A45: G- | B45: Implementatin Cost with SAP Migration Project (5year) | D45: 1 | E45: Local | F45: Feb'27 | H45: 40000000
E47: TOTAL- >>>>>> B-4 | H47: =SUM(H39:H45) -> 54625885
...

Sheet RM-SUMMARY
A1: AGRIAUTO STAMPING COMPANY PVT LIMITED
A2: REPAIR & MAINTENANCE BUDGET - STAMPING & CATALYTIC CONVERTOR
A3: 2026-27
A5: Sr. # | B5: DESCRIPTION OF ITEM | C5: QTY. | D5: NEW USED/REFUR | E5: IMPORT / LOCAL | F5: FY 2025-26 (Rs.) | G5: Act Est. 2025-26 (Rs.) | H5: FY 2026-27 (Rs.) | I5: Differ | WZI5: Budget Utilization | WZJ5: Remaining budget | WZK5: Utilization %
A7: A | B7: Annual Service contracts | E7: Local | F7: ='RM Detail'!F19 -> 7725000 | G7: ='RM Detail'!G19 -> 5052208 | H7: ='RM Detail'!H19 -> 7850000 | I7: =H7-G7 -> 2797792
A9: B | B9: Critical Machine Spares, Tools | E9: Import | F9: ='RM Detail'!F33 -> 20141720 | G9: ='RM Detail'!G33 -> 26719621 | H9: ='RM Detail'!H33 -> 26277194 | I9: =H9-G9 -> -442426.54
I10: =H10-G10 -> 0
A11: C | B11: Improvement & Repair works | E11: Import | F11: ='RM Detail'!F62 -> 16099295 | G11: ='RM Detail'!G62 -> 12029634 | H11: ='RM Detail'!H62 -> 16660500 | I11: =H11-G11 -> 4630866
I12: =H12-G12 -> 0
A13: D | B13: Truck & Forklifter Maintenance | E13: Local | F13: ='RM Detail'!F77 -> 2420000 | G13: ='RM Detail'!G77 -> 4111146.6 | H13: ='RM Detail'!H77 -> 7675329.7 | I13: =H13-G13 -> 3564183
I14: =H14-G14 -> 0
A15: E | B15: General Maintenance & Items | E15: Local | F15: ='RM Detail'!F96 -> 11745732 | G15: ='RM Detail'!G96 -> 16325234 | H15: ='RM Detail'!H96 -> 15668402 | I15: =H15-G15 -> -656831.85
I16: =H16-G16 -> 0
A17: F | B17: Quality | E17: Local | F17: ='RM Detail'!F111 -> 4329300 | G17: ='RM Detail'!G111 -> 2333954 | H17: ='RM Detail'!H111 -> 2487000 | I17: =H17-G17 -> 153046
I18: =H18-G18 -> 0
A19: G | B19: Hand Tools | E19: Local | F19: ='RM Detail'!F119 -> 2355615 | G19: ='RM Detail'!G119 -> 1910042.5 | H19: ='RM Detail'!H119 -> 3468365 | I19: =H19-G19 -> 1558322.5
I20: =H20-G20 -> 0
A21: H | B21: Admin | E21: Local | F21: ='RM Detail'!F131 -> 1600000 | G21: ='RM Detail'!G131 -> 3092968.2 | H21: ='RM Detail'!H131 -> 4300000 | I21: =H21-G21 -> 1207031.8
I22: =H22-G22 -> 0
A23: I | B23: IT | E23: Local | F23: ='RM Detail'!F161 -> 8803912 | G23: ='RM Detail'!G161 -> 6853605 | H23: ='RM Detail'!H161 -> 28324568 | I23: =H23-G23 -> 21470963
I24: =H24-G24 -> 0
A25: J | B25: Oil / Lubricants | E25: Local | F25: ='RM Detail'!F166 -> 4966140 | G25: ='RM Detail'!G166 -> 4828162 | H25: ='RM Detail'!H166 -> 0 | I25: =H25-G25 -> -4828162
I26: =H26-G26 -> 0
A27: K | B27: Material Handling | E27: Local | F27: ='RM Detail'!F172 -> 10397008 | G27: ='RM Detail'!G172 -> 14411500 | H27: ='RM Detail'!H172 -> 15000000 | I27: =H27-G27 -> 588500
I28: =H28-G28 -> 0
A29: L | B29: Sap Rise | E29: Local | H29: ='RM Detail'!H177 -> 58000000 | I29: =H29-G29 -> 58000000
I30: =H30-G30 -> 0
I31: =H31-G31 -> 0
D32: GRAND TOTAL | F32: =SUM(F7:F31) -> 90583722 | G32: =SUM(G7:G31) -> 97668075 | H32: =SUM(H7:H31) -> 1.8571136e+08 | I32: =H32-G32 -> 88043284

Sheet RM Detail
A1: AGRIAUTO STAMPING COMPANY PVT LIMITED
A2: REPAIR & MAINTENANCE BUDGET
A3: 2026-27
I4: Approved
A5: Sr. # | B5: DESCRIPTION OF ITEM | C5: QTY. | D5: NEW USED/REFUR | E5: IMPORT / LOCAL | F5: Budgeted Amount (Rs.) | G5: Budget Utilization | H5: Proposed Budget 26-27 | I5: Budget Utilization | J5: Remaining budget | L5: 2000005372 | M5: 2000005358 | N5: 2000005356 | O5: 2000005403 | P5: 2000005494 | Q5: 2000005476
A7: A | B7: Annual Service contracts
A8: 1- | B8: Weigh Bridge Calibration & Service Contract | C8: 1 | D8: New | E8: Local | F8: 50000 | G8: 48825 | H8: 50000 | I8: =SUM(L8:XEZ8) -> 0 | J8: =H8-I8 -> 50000
A9: 2- | B9: Overhead Crane 20 T + 20/10T, GH Crane and Street Crane | C9: 4 | D9: New | E9: Local | F9: =1350000 -> 1350000 | G9: 1306024 | H9: =1350000 -> 1350000 | I9: =SUM(L9:XEZ9) -> 0 | J9: =H9-I9 -> 1350000
A10: 3- | B10: Vibration Analysis (4 Times/Year) | C10: 6 | D10: New | E10: Local | F10: 250000 | G10: 0 | H10: 250000 | I10: =SUM(L10:XEZ10) -> 0 | J10: =H10-I10 -> 250000
A11: 4- | B11: Compressor efficiency analysis by AVS (6 Times/ Yr) | C11: 6 | D11: New | E11: Local | F11: 150000 | G11: 307530 | H11: 450000 | I11: =SUM(L11:XEZ11) -> 0 | J11: =H11-I11 -> 450000
A12: 5- | B12: Generator 135KVA | C12: 1 | D12: New | E12: Local | F12: 100000 | G12: 0 | H12: 100000 | I12: =SUM(L12:XEZ12) -> 0 | J12: =H12-I12 -> 100000
A13: 6- | B13: Horiuchi Contract for Press machines | C13: 5 | D13: New | E13: Local/Import | F13: 3000000 | G13: 546170 | H13: 3000000 | I13: =SUM(L13:XEZ13) -> 0 | J13: =H13-I13 -> 3000000
A14: 7- | B14: Solar Maintenance Annual Contract REON | C14: 1 | D14: New | E14: Local | F14: 2200000 | G14: 2282276 | H14: 2000000 | I14: =SUM(L14:XEZ14) -> 0 | J14: =H14-I14 -> 2000000
A15: 8- | B15: Annual Service Contract for CCTV Camera System | C15: 1 | D15: New | E15: Local | F15: 175000 | G15: 180000 | H15: 200000 | I15: =SUM(L15:XEZ15) -> 0 | J15: =H15-I15 -> 200000
A16: 9- | B16: Annual Service Contract for Canteen Lift | C16: 1 | D16: New | E16: Local | F16: 250000 | G16: 196600 | H16: 250000 | I16: =SUM(L16:XEZ16) -> 0 | J16: =H16-I16 -> 250000
A17: 10- | B17: Annual Service Contract for Attendance Machine | C17: 1 | D17: New | E17: Local | F17: 200000 | G17: 184783 | H17: 200000 | I17: =SUM(L17:XEZ17) -> 0 | J17: =H17-I17 -> 200000
A19: Sub Total (A): | F19: =SUM(F8:F17) -> 7725000 | G19: =SUM(G8:G17) -> 5052208 | H19: =SUM(H8:H17) -> 7850000 | I19: =SUM(I8:I17) -> 0 | J19: =SUM(J8:J17) -> 7850000
A20: B | B20: Critical Machine Spares Backup:
A21: 1- | B21: Stamping Shop | C21: 9 | D21: New/Refurbished | E21: Import/Local | F21: 4000000 | G21: 5250525.3 | H21: 3500000 | I21: =SUM(L21:XEZ21) -> 0 | J21: =H21-I21 -> 3500000
A22: 2- | B22: Over Head Cranes 20T & 20/10T | C22: 4 | D22: New/Refurbished | E22: Import/Local | F22: 4000000 | G22: 5100500.3 | H22: 2000000 | I22: =SUM(L22:XEZ22) -> 0 | J22: =H22-I22 -> 2000000
A23: 3- | B23: Weld Shop (Maintenance Spares) | C23: var | D23: New/Refurbished | E23: Import/Local | F23: 3500000 | G23: 4079725.7 | H23: 4000000 | I23: =SUM(L23:XEZ23) -> 0 | J23: =H23-I23 -> 4000000
A24: 4- | B24: Weld Shop (Production Spares) | C24: Var | D24: New/Refurbished | E24: Import/Local | F24: 491720 | G24: 516470 | H24: 790194 | I24: =SUM(L24:XEZ24) -> 0 | J24: =H24-I24 -> 790194
A25: 5- | B25: Die Center Machines | C25: 7 | D25: New/Refurbished | E25: Import/Local | F25: 1000000 | G25: 800000 | H25: 1000000 | I25: =SUM(L25:XEZ25) -> 0 | J25: =H25-I25 -> 1000000
A26: 6- | B26: Cooling Tower Spares | C26: 2 | D26: New | E26: Local | F26: 750000 | G26: 535747 | H26: 950000 | I26: =SUM(L26:XEZ26) -> 0 | J26: =H26-I26 -> 950000
A27: 7- | B27: Repairing of Chillers | C27: 3 | D27: New | E27: Local | F27: 650000 | G27: 530000 | H27: 287000 | I27: =SUM(L27:XEZ27) -> 0 | J27: =H27-I27 -> 287000
A28: 8- | B28: Catalytic Convertor Plant Machine spares | C28: 11 | D28: New | E28: Import/Local | F28: 1000000 | G28: 2150000 | H28: 3500000 | I28: =SUM(L28:XEZ28) -> 0 | J28: =H28-I28 -> 3500000
A29: 9- | B29: Compressor & Dryers Service Kits & Spare Parts | C29: 6 | D29: New | E29: Import/Local | F29: 4500000 | G29: 5285091.3 | H29: 6500000 | I29: =SUM(L29:XEZ29) -> 0 | J29: =H29-I29 -> 6500000
A30: 10- | B30: Canteen Lift Critical Spares | C30: 1 | D30: New | E30: Local | F30: 250000 | G30: 210000 | H30: 250000 | I30: =SUM(L30:XEZ30) -> 0 | J30: =H30-I30 -> 250000
A31: 11- | B31: All Plant Machine Inverters (VFDs) | G31: 2261561 | H31: 3500000 | J31: =H31-I31 -> 3500000
A33: Sub Total (B): | F33: =SUM(F21:F30) -> 20141720 | G33: =SUM(G21:G31) -> 26719621 | H33: =SUM(H21:H32) -> 26277194 | I33: =SUM(I21:I32) -> 0 | J33: =SUM(J21:J32) -> 26277194
A35: C | B35: Improvement & Repair works
B36: Compressor Overhauling | C36: 2 | D36: New | E36: Local | F36: NR
A37: 1- | B37: Coloring work (Utility building & Plant) | C37: var | D37: New | E37: Local | F37: =1000000 -> 1000000 | G37: 637820 | H37: 500000 | I37: =SUM(L37:XEZ37) -> 0 | J37: =H37-I37 -> 500000
A38: 2- | B38: Coloring Work of All Komatsu Press Machine | C38: 4 | D38: New | E38: Local | F38: 550000 | G38: 550000 | H38: 0 | I38: =SUM(L38:XEZ38) -> 0 | J38: =H38-I38 -> 0
A39: 3- | B39: Repair, repaint of bins, racks and trolleys etc | C39: var | D39: New | E39: Local | F39: 500000 | G39: 135891 | H39: 500000 | I39: =SUM(L39:XEZ39) -> 0 | J39: =H39-I39 -> 500000
A40: 4- | B40: Wheel & Color for Scrap Bins (Press Shop) | C40: Var | D40: New | E40: Local | F40: 118800 | G40: 0 | H40: 170500 | I40: =SUM(L40:XEZ40) -> 0 | J40: =H40-I40 -> 170500
A41: 5- | B41: Halogen Bulb Replacement with LED Lights DDC& Press Area | C41: Var | D41: New | E41: Local | F41: 1020000 | G41: 1013564.1 | H41: 500000 | I41: =SUM(L41:XEZ41) -> 0 | J41: =H41-I41 -> 500000
A42: 6- | B42: LED's Replacement Whole Plant | C42: Var | D42: New | E42: Local | F42: 3000000 | G42: 2699682 | H42: 0 | I42: =SUM(L42:XEZ42) -> 0 | J42: =H42-I42 -> 0
A43: 7- | B43: Fire Alarm Maintenance | C43: 1 | D43: New | E43: Local | F43: 350000 | G43: 199600 | H43: 350000 | I43: =SUM(L43:XEZ43) -> 0 | J43: =H43-I43 -> 350000
A44: 8- | B44: All Plant AC/Refrigeration Repair & Maintenance | C44: Var | D44: New | E44: Local | F44: 750000 | G44: 278000 | H44: 750000 | I44: =SUM(L44:XEZ44) -> 0 | J44: =H44-I44 -> 750000
...

Sheet Consuambles
A1: AGRIAUTO STAMPING COMPANY (PVT.) LTD.
A2: CONSUMABLES STORES
D4: BUDGET 2022-23 | K4: BUDGET 2023-24 | P4: BUDGET 2025-26 | X4: BUDGET 2026-27
A5: S.no | B5: Material Number | C5: Description | D5: Qty | E5: UOM | F5: Rate | G5: 20% Increase | H5: Increase Price | I5: Total | K5: Qty | L5: UOM | M5: Rate | N5: Total | P5: Qty | Q5: UOM | R5: Rate | S5: Total | U5: CONSUMPTION 1-1-2025 -- 1-1-2026 | V5: CONSUMPTION 1.1.2026 - 30.4.2026 | W5: QUARTER x 4 | X5: Qty | Y5: UOM | Z5: Rate | AA5: Total | AB5: UTILIZATION UPTO APR 26 | AC5: UTILIZATION UPTO JUN 26 | AD5: REASON | AF5: Budget Utilization | AG5: Remaining budget | AI5: 2000005366 | AJ5: 2000005365
A7: 1 | B7: PRC1-GEN-00003 | C7: Netted Gloves | D7: 60000 | E7: Sets | F7: 20 | G7: 4 | H7: 24 | I7: 1440000 | K7: 24000 | L7: Sets | M7: 20 | N7: 480000 | P7: 36000 | Q7: Sets | R7: 32 | S7: 1152000 | U7: 49104 | V7: 21984 | W7: 65952 | X7: 80000 | Y7: Sets | Z7: 30 | AA7: 2400000 | AB7: 1580011.6 | AC7: 1896013.9 | AD7: General reason : 79 man power increased from Last year with added C shift and upcoming new products in next year i.e. W&D and YXO | AF7: =SUM(AH7:XFD7) -> 0 | AG7: =AA7-AF7 -> 2400000
A8: 2 | B8: PRC1-GEN-00012 | C8: Kevlar Gloves | D8: 1200 | E8: Sets | F8: 480 | G8: 96 | H8: 576 | I8: 691200 | K8: 400 | L8: Sets | M8: 480 | N8: 192000 | P8: 600 | Q8: Sets | R8: 480 | S8: 288000 | U8: 647 | V8: 504 | W8: 1512 | X8: 1600 | Y8: Sets | Z8: 528 | AA8: 844800 | AB8: 486000 | AC8: 583200 | AF8: =SUM(AH8:XFD8) -> 0 | AG8: =AA8-AF8 -> 844800
A9: 3 | B9: PRC1-GEN-00001 | C9: Cotton Rags | D9: 3600 | E9: Kg | F9: 60 | G9: 12 | H9: 72 | I9: 259200 | K9: 1700 | L9: Kg | M9: 95 | N9: 161500 | P9: 2000 | Q9: Kg | R9: 95 | S9: 190000 | U9: 1997 | V9: 680 | W9: 2040 | X9: 2500 | Y9: KG | Z9: 95 | AA9: 237500 | AB9: 184300 | AC9: 221160 | AF9: =SUM(AH9:XFD9) -> 0 | AG9: =AA9-AF9 -> 237500
A10: 4 | B10: LUB-GEN-00003 | C10: Kerosene Oil | D10: 2400 | E10: Lts | F10: 210 | G10: 42 | H10: 252 | I10: 604800 | K10: 900 | L10: Ltr | M10: 325 | N10: 292500 | P10: 1200 | Q10: Ltr | R10: 320 | S10: 384000 | U10: 1309 | V10: 430 | W10: 1290 | X10: 1600 | Y10: Ltr | Z10: 320 | AA10: 512000 | AB10: 412550.19 | AC10: 495060.23 | AF10: =SUM(AH10:XFD10) -> 0 | AG10: =AA10-AF10 -> 512000
A11: 5 | B11: LUB-GEN-00018 | C11: SunRess Oil | D11: 600 | E11: Ltr | F11: 2570 | G11: 514 | H11: 3084 | I11: 1850400 | K11: 200 | L11: Ltr | M11: 6906 | N11: 1381200 | P11: 200 | Q11: Ltr | R11: 6906 | S11: 1381200 | U11: 357 | V11: 170 | W11: 510 | X11: 200 | Y11: Ltr | Z11: 6906 | AA11: 1381200 | AB11: 2176145.4 | AC11: 2611374.5 | AF11: =SUM(AH11:XFD11) -> 0 | AG11: =AA11-AF11 -> 1381200
A12: 6 | C12: JIER Line (Oil Replace) | X12: 4 | AA12: 4800000 | AF12: =SUM(AH12:XFD12) -> 0 | AG12: =AA12-AF12 -> 4800000
A13: 7 | C13: Cutting and Lubrication OIL for DDC | X13: 2 | AA13: 621425 | AF13: =SUM(AH13:XFD13) -> 0 | AG13: =AA13-AF13 -> 621425
A14: 8 | B14: CON-OLB-0007 | C14: Anticore 40 | D14: 1600 | E14: Ltr | F14: 350 | G14: 70 | H14: 420 | I14: 672000 | K14: 1800 | L14: Ltr | M14: 570 | N14: 1026000 | P14: 2000 | Q14: Ltr | R14: 598 | S14: 1196000 | U14: 2780 | V14: 780 | W14: 2340 | X14: 2800 | Y14: Ltr | Z14: 885 | AA14: 2478000 | AB14: 1451320 | AC14: 1741584 | AF14: =SUM(AH14:XFD14) -> 0 | AG14: =AA14-AF14 -> 2478000
A15: 9 | B15: HRD-WRE-00014 | C15: Cutting Disc 4" 1mm Rodius | D15: 1000 | E15: Nos | F15: 137 | G15: 27.4 | H15: 164.4 | I15: 164400 | K15: 300 | L15: Ea | M15: 200 | N15: 60000 | P15: 1500 | Q15: Ea | R15: 210 | S15: 315000 | U15: 712 | V15: 266 | W15: 798 | X15: 1000 | Y15: Ea | Z15: 210 | AA15: 210000 | AB15: 116785.86 | AC15: 140143.03 | AF15: =SUM(AH15:XFD15) -> 0 | AG15: =AA15-AF15 -> 210000
A16: 10 | B16: PRC1-GEN-00134 | C16: Argon Gas (Cylinder) | D16: 480 | E16: ea | F16: 3000 | G16: 600 | H16: 3600 | I16: 1728000 | K16: 200 | L16: Ea | M16: 4000 | N16: 800000 | P16: 150 | Q16: Ea | R16: 4000 | S16: 600000 | U16: 208 | V16: 84 | W16: 252 | X16: 230 | Y16: Ea | Z16: 4000 | AA16: 920000 | AB16: 760000 | AC16: 912000 | AF16: =SUM(AH16:XFD16) -> 0 | AG16: =AA16-AF16 -> 920000
A17: 11 | B17: MECH-ITM-00024 | C17: Arm Sleeves | D17: 2000 | E17: Sets | F17: 180 | G17: 36 | H17: 216 | I17: 432000 | K17: 200 | L17: Sets | M17: 180 | N17: 36000 | P17: 400 | Q17: Sets | R17: 200 | S17: 80000 | U17: 538 | V17: 283 | W17: 849 | X17: 1000 | Y17: Sets | Z17: 225 | AA17: 225000 | AB17: 126543.86 | AC17: 151852.63 | AF17: =SUM(AH17:XFD17) -> 0 | AG17: =AA17-AF17 -> 225000
A18: 12 | B18: PRC1-GEN-000012 | C18: Wrist Supporter | D18: 1600 | E18: Sets | F18: 170 | G18: 34 | H18: 204 | I18: 326400 | K18: 200 | L18: Sets | M18: 170 | N18: 34000 | P18: 350 | Q18: Sets | R18: 170 | S18: 59500 | U18: 389 | V18: 165 | W18: 495 | X18: 620 | Y18: Sets | Z18: 170 | AA18: 105400 | AB18: 69530 | AC18: 83436 | AF18: =SUM(AH18:XFD18) -> 0 | AG18: =AA18-AF18 -> 105400
A19: 13 | B19: PRC1-GEN-00007 | C19: Apron | D19: 1600 | E19: Nos | F19: 240 | G19: 48 | H19: 288 | I19: 460800 | K19: 100 | L19: Nos | M19: 315 | N19: 31500 | P19: 420 | Q19: Nos | R19: 210 | S19: 88200 | U19: 641 | V19: 249 | W19: 747 | X19: 850 | Y19: Nos | Z19: 210 | AA19: 178500 | AB19: 123480 | AC19: 148176 | AF19: =SUM(AH19:XFD19) -> 0 | AG19: =AA19-AF19 -> 178500
A20: 14 | B20: MECH-ITM-00020 | C20: Face shield welding | D20: 600 | E20: Nos | F20: 410 | G20: 82 | H20: 492 | I20: 295200 | K20: 150 | L20: Nos | M20: 300 | N20: 45000 | P20: 200 | Q20: Nos | R20: 350 | S20: 70000 | U20: 410 | V20: 185 | W20: 555 | X20: 680 | Y20: Nos | Z20: 600 | AA20: 408000 | AB20: 169900 | AC20: 203880 | AF20: =SUM(AH20:XFD20) -> 0 | AG20: =AA20-AF20 -> 408000
A21: 15 | B21: PRC1-GEN-00133 | C21: Ear Plugs | D21: 3600 | E21: Nos. | F21: 30 | G21: 6 | H21: 36 | I21: 129600 | K21: 150 | L21: Nos | M21: 35 | N21: 5250 | P21: 300 | Q21: Nos | R21: 23 | S21: 6900 | U21: 301 | V21: 121 | W21: 363 | X21: 450 | Y21: Nos | Z21: 23 | AA21: 10350 | AB21: 6785 | AC21: 8142 | AF21: =SUM(AH21:XFD21) -> 0 | AG21: =AA21-AF21 -> 10350
A22: 16 | B22: PRC1-GEN-00004 | C22: Dust Mask | D22: 20000 | E22: Nos | F22: 2.2 | G22: 0.44 | H22: 2.64 | I22: 52800 | N22: 0 | P22: 800 | Q22: Nos | R22: 1.25 | S22: 1000 | U22: 1129 | V22: 732 | W22: 2196 | X22: 3000 | Y22: Nos | Z22: 3 | AA22: 9000 | AB22: 1967.38 | AC22: 2360.856 | AF22: =SUM(AH22:XFD22) -> 0 | AG22: =AA22-AF22 -> 9000
A23: 17 | B23: MECH-ITM-00076 | C23: Safety Goggle | D23: 900 | E23: Nos. | F23: 200 | G23: 40 | H23: 240 | I23: 216000 | K23: 250 | L23: Nos | M23: 200 | N23: 50000 | P23: 300 | Q23: Nos | R23: 325 | S23: 97500 | U23: 377 | V23: 161 | W23: 483 | X23: 550 | Y23: Nos | Z23: 325 | AA23: 178750 | AB23: 113100 | AC23: 135720 | AD23: 278 CURRENT MAN POWER & 312 MAN POWER | AF23: =SUM(AH23:XFD23) -> 0 | AG23: =AA23-AF23 -> 178750
A24: 18 | B24: ERSA-SPARE-001568 | C24: Bump Caps | D24: 120 | E24: Nos | F24: 410 | G24: 82 | H24: 492 | I24: 59040 | K24: 20 | L24: Nos | M24: 450 | N24: 9000 | P24: 50 | Q24: Nos | R24: 1230 | S24: 61500 | U24: 41 | V24: 4 | W24: 12 | X24: 100 | Y24: Nos | Z24: 1210 | AA24: 121000 | AB24: 15976.45 | AC24: 19171.74 | AD24: -34 | AF24: =SUM(AH24:XFD24) -> 0 | AG24: =AA24-AF24 -> 121000
A25: 19 | B25: ERSA-SPARE-001499 | C25: Cutter Baldes | D25: 50 | E25: Sets | F25: 8882 | G25: 1776.4 | H25: 10658.4 | I25: 532920 | N25: 0 | P25: 50 | Q25: Nos | R25: 7500 | S25: 375000 | U25: 80 | V25: 24 | W25: 72 | X25: 100 | Y25: Nos | Z25: 7500 | AA25: 750000 | AB25: 532880.02 | AC25: 639456.02 | AF25: =SUM(AH25:XFD25) -> 0 | AG25: =AA25-AF25 -> 750000
A26: 20 | B26: ERSA-SPARE-001498 | C26: Weld Tip YT-16-D3-C | D26: 2000 | E26: Nos | F26: 225 | G26: 45 | H26: 270 | I26: 540000 | K26: 1000 | L26: Nos | M26: 280 | N26: 280000 | P26: 3000 | Q26: Nos | R26: 380 | S26: 1140000 | U26: 3770 | V26: 1500 | W26: 4500 | X26: 5000 | Y26: Nos | Z26: 385 | AA26: 1925000 | AB26: 1385500 | AC26: 1662600 | AF26: =SUM(AH26:XFD26) -> 0 | AG26: =AA26-AF26 -> 1925000
A27: 21 | B27: MECH-ITM-00632 | C27: Weld Tip W-CTR-13X6A | D27: 0 | E27: Nos | F27: 176 | G27: 35.2 | H27: 211.2 | I27: 0 | N27: 0 | P27: 1000 | Q27: Nos | R27: 335 | S27: 335000 | U27: 500 | V27: 200 | W27: 600 | X27: 700 | Y27: Nos | Z27: 355 | AA27: 248500 | AB27: 134552.96 | AC27: 161463.55 | AF27: =SUM(AH27:XFD27) -> 0 | AG27: =AA27-AF27 -> 248500
A28: 22 | B28: CON-GAS-0008 | C28: CO2 Cylinders for Gas Welding | D28: 100 | E28: Nos | F28: 1760 | G28: 352 | H28: 2112 | I28: 211200 | K28: 20 | L28: Nos | M28: 1760 | N28: 35200 | P28: 60 | Q28: Nos | R28: 1760 | S28: 105600 | U28: 95 | V28: 54 | W28: 162 | X28: 200 | Y28: Nos | Z28: 1760 | AA28: 352000 | AB28: 202400 | AC28: 242880 | AF28: =SUM(AH28:XFD28) -> 0 | AG28: =AA28-AF28 -> 352000
A29: 23 | B29: NSM-GEN-00093 | C29: Grease | D29: 180 | E29: Kg | F29: 360 | G29: 72 | H29: 432 | I29: 77760 | K29: 60 | L29: Kg | M29: 496 | N29: 29760 | P29: 64 | Q29: Kg | R29: 1325 | S29: 84800 | U29: 80 | V29: 7 | W29: 21 | X29: 80 | Y29: Kg | Z29: 1425 | AA29: 114000 | AB29: 91300 | AC29: 109560 | AF29: =SUM(AH29:XFD29) -> 0 | AG29: =AA29-AF29 -> 114000
A30: 24 | B30: PRC1-GEN-00418 | C30: LPG Gas Cylinders for Canteen | D30: 100 | E30: Ea | F30: 2200 | G30: 440 | H30: 2640 | I30: 264000 | K30: 90 | L30: Nos | M30: 3000 | N30: 270000 | P30: 60 | Q30: Nos | R30: 2500 | S30: 150000 | U30: 38 | V30: 15 | W30: 45 | X30: 50 | Y30: Nos | Z30: 2500 | AA30: 125000 | AB30: 85000 | AC30: 102000 | AF30: =SUM(AH30:XFD30) -> 0 | AG30: =AA30-AF30 -> 125000
A31: 25 | B31: ERSA-SPARE-001592 | C31: Brazing Rods | D31: 15 | E31: Packets | F31: 24300 | G31: 4860 | H31: 29160 | I31: 437400 | N31: 0 | P31: 50 | Q31: Nos | R31: 3000 | S31: 150000 | U31: 82 | V31: 37 | W31: 111 | X31: 100 | Y31: Nos | Z31: 6000 | AA31: 600000 | AB31: 346500 | AC31: 415800 | AF31: =SUM(AH31:XFD31) -> 0 | AG31: =AA31-AF31 -> 600000
A32: 26 | B32: XYZ | C32: Paint (Grey / White / Green / Black / Yellow / Red) | D32: 100 | E32: Tin | F32: 2200 | G32: 440 | H32: 2640 | I32: 264000 | K32: 72 | L32: Tin | M32: 3650 | N32: 262800 | P32: 100 | Q32: Tin | R32: 3850 | S32: 385000 | W32: 100 | X32: 100 | Y32: Tin | Z32: 3900 | AA32: 390000 | AB32: 161150.72 | AC32: 193380.86 | AF32: =SUM(AH32:XFD32) -> 0 | AG32: =AA32-AF32 -> 390000
A33: 27 | B33: MECH-ITM-00012 | C33: Cutting Discs 14" Rodius | D33: 70 | E33: Nos | F33: 640 | G33: 128 | H33: 768 | I33: 53760 | K33: 20 | L33: Nos | M33: 800 | N33: 16000 | P33: 100 | Q33: Nos | R33: 840 | S33: 84000 | U33: 15 | V33: 15 | W33: 45 | X33: 50 | Y33: Nos | Z33: 1425 | AA33: 71250 | AB33: 21000 | AC33: 25200 | AF33: =SUM(AH33:XFD33) -> 0 | AG33: =AA33-AF33 -> 71250
A34: 28 | B34: MECH-ITM-00013 | C34: Cutting Disc 7" Rodius | D34: 200 | E34: Nos | F34: 242 | G34: 48.4 | H34: 290.4 | I34: 58080 | N34: 0 | P34: 400 | Q34: Nos | R34: 375 | S34: 150000 | U34: 140 | V34: 25 | W34: 75 | X34: 200 | Y34: Nos | Z34: 375 | AA34: 75000 | AB34: 52500 | AC34: 63000 | AF34: =SUM(AH34:XFD34) -> 0 | AG34: =AA34-AF34 -> 75000
A35: 29 | B35: TOOL-GEN-00058 | C35: Grinding Disc 4" Rodius | D35: 450 | E35: Nos | F35: 175 | G35: 35 | H35: 210 | I35: 94500 | N35: 0 | P35: 600 | Q35: Nos | R35: 250 | S35: 150000 | U35: 133 | V35: 20 | W35: 60 | X35: 133 | Y35: Nos | Z35: 250 | AA35: 33250 | AB35: 10460.51 | AC35: 12552.612 | AF35: =SUM(AH35:XFD35) -> 0 | AG35: =AA35-AF35 -> 33250
A36: 30 | B36: HRD-WRE-00325 | C36: FLAP DISC 4" X 5/8" | D36: 1200 | E36: Nos | F36: 90 | G36: 18 | H36: 108 | I36: 129600 | K36: 150 | L36: Nos | M36: 90 | N36: 13500 | P36: 600 | Q36: Nos | R36: 88 | S36: 52800 | U36: 545 | V36: 200 | W36: 600 | X36: 650 | Y36: Nos | Z36: 90 | AA36: 58500 | AB36: 46618.12 | AC36: 55941.744 | AF36: =SUM(AH36:XFD36) -> 0 | AG36: =AA36-AF36 -> 58500
A37: 31 | B37: MECH-ITM-00886 | C37: Cutting Disc 5" Rodius | D37: 600 | E37: Nos | F37: 150 | G37: 30 | H37: 180 | I37: 108000 | K37: 100 | L37: Nos. | M37: 250 | N37: 25000 | P37: 500 | Q37: Nos | R37: 225 | S37: 112500 | U37: 327 | V37: 173 | W37: 519 | X37: 500 | Y37: Nos | Z37: 235 | AA37: 117500 | AB37: 68250 | AC37: 81900 | AF37: =SUM(AH37:XFD37) -> 0 | AG37: =AA37-AF37 -> 117500
A38: 32 | B38: MECH-ITM-00001 | C38: Welding Rods 2.5mm Zodian | D38: 90 | E38: Packets | F38: 1100 | G38: 220 | H38: 1320 | I38: 118800 | K38: 30 | L38: Packets | M38: 2235 | N38: 67050 | P38: 120 | Q38: Packets | R38: 2280 | S38: 273600 | U38: 62 | V38: 25 | W38: 75 | X38: 120 | Y38: Packets | Z38: 2280 | AA38: 273600 | AB38: 146220 | AC38: 175464 | AF38: =SUM(AH38:XFD38) -> 0 | AG38: =AA38-AF38 -> 273600
A39: 33 | B39: HRD-WRE-00015 | C39: Welding Rods 3.2mm Zodian | D39: 60 | E39: Packets | F39: 1700 | G39: 340 | H39: 2040 | I39: 122400 | K39: 40 | L39: Packets | M39: 3475 | N39: 139000 | P39: 70 | Q39: Packets | R39: 3773.75 | S39: 264162.5 | U39: 19 | V39: 8 | W39: 24 | X39: 40 | Y39: Packets | Z39: 3773.75 | AA39: 150950 | AB39: 75178.91 | AC39: 90214.692 | AF39: =SUM(AH39:XFD39) -> 0 | AG39: =AA39-AF39 -> 150950
A40: 34 | B40: HRD-WRE-00324 | C40: Cup Wire brush | D40: 1000 | E40: No. | F40: 120 | G40: 24 | H40: 144 | I40: 144000 | K40: 500 | L40: No. | M40: 145 | N40: 72500 | P40: 600 | Q40: Nos | R40: 280 | S40: 168000 | U40: 199 | V40: 79 | W40: 237 | X40: 250 | Y40: Nos | Z40: 280 | AA40: 70000 | AB40: 55160 | AC40: 66192 | AF40: =SUM(AH40:XFD40) -> 0 | AG40: =AA40-AF40 -> 70000
A41: 35 | B41: ERSA-SPARE-001750 | C41: REVOLVING WHEEL 6" | D41: 60 | E41: No. | F41: 1000 | G41: 200 | H41: 1200 | I41: 72000 | K41: 20 | L41: No. | M41: 1400 | N41: 28000 | P41: 150 | Q41: Nos | R41: 1050 | S41: 157500 | U41: 300 | V41: #N/A | W41: #N/A | X41: 400 | Y41: Nos | Z41: 1150 | AA41: 460000 | AB41: 278250 | AC41: 333900 | AF41: =SUM(AH41:XFD41) -> 0 | AG41: =AA41-AF41 -> 460000
A42: 36 | B42: ERSA-SPARE-000267 | C42: FIX WHEEL 6" | D42: 60 | E42: No. | F42: 880 | G42: 176 | H42: 1056 | I42: 63360 | K42: 20 | L42: No. | M42: 1200 | N42: 24000 | P42: 30 | Q42: Nos | R42: 1020 | S42: 30600 | U42: 84 | V42: #N/A | W42: #N/A | X42: 120 | Y42: Nos | Z42: 1050 | AA42: 126000 | AB42: 85369.57 | AC42: 102443.48 | AF42: =SUM(AH42:XFD42) -> 0 | AG42: =AA42-AF42 -> 126000
...

Sheet Sales Promotion Budget
B2: Sales Promotion Budget - 2026/27
C4: Exp. Rate | D4: Nos. | E4: Exp. Budget | G4: LY Actual
B6: Corporate Video: Edit to Add diversification Portion | C6: 250000 | D6: 1 | E6: 250000 | G6: 1800000 | H6: asc
B8: After Market Promotional Exp.
B9: Dealer Incentive | D9: 0.06 | E9: =K9*D9 -> 81000000 | G9: =1150000000*6% -> 69000000 | H9: ail | I9: =E9-G9 -> 12000000 | J9: Dealer Sale | K9: =K11-K10 -> 1350000000 | M9: =K11*0.06 -> 84000000
B10: Dealer/Mechanic Meet | C10: 1300000 | D10: 3 | E10: =D10*C10 -> 3900000 | G10: 2049119 | H10: asc | J10: Others | K10: 50000000
E11: =SUM(E9:E10) -> 84900000 | G11: =SUM(G9:G10) -> 71049119 | K11: 1400000000
B13: Advertising Agency - Retainership Fee | E13: 900000 | G13: 305268
B15: General Promotional Items Exp
B16: P-Cap | C16: 650 | D16: 1000 | E16: =D16*C16 -> 650000
B17: T-Shirt | C17: 2000 | D17: 1000 | E17: =D17*C17 -> 2000000
B18: Note Book | C18: 300 | D18: 1000 | E18: =D18*C18 -> 300000
B19: Miscellaneous (Broacher & Others) | E19: 300000
B20: Executive Giveaways | C20: 6500 | D20: 50 | E20: =D20*C20 -> 325000
E21: =SUM(E16:E20) -> 3575000 | G21: 927525 | H21: asc
B23: Shock Absorber - Export
B24: Exhibition Participation (Shocks/Brake Pads)- Jun'27 | C24: @ $5392 | D24: 1 | E24: =[52]istanbul!I26 -> 1586800 | H24: asc
B25: Petromin Samples (10 Types - 2 each) | E25: 206000 | H25: ail
E26: =SUM(E24:E25) -> 1792800
B27: Power Sector
B28: Enfrashare Sample | E28: 400000 | H28: ail
B29: Ed Boxes for ABAD 9@ 30k each ( Display) | E29: 270000 | H29: ail
B30: Power Sector - Educational order approval expenses. (LESCO) | E30: 2000000 | H30: asc
B31: FOC Educational Order Meter Boxes LESCO (5@40k) | E31: 800000 | H31: ail
E32: =SUM(E28:E31) -> 3470000 | G32: =153022+56000 -> 209022
B34: Waiting Chair
B35: Salesman Incentive | C35: 1000/Chair | D35: 2800 | H35: ail
B36: Exhibition Participation ( IAPEX LHR/KHI) | C36: 1500000 | D36: 1 | E36: =D36*C36 -> 1500000 | H36: asc
B37: Advertising ( Magazine Ads, BR/NW/Dawn) 2 inserts | E37: 1000000 | H37: asc
B38: Upholstery Color Selectors Shade Samples for Customers | C38: 100 | D38: 500 | E38: =D38*C38 -> 50000 | H38: ail
B39: Paid visits to Plant of Partners | E39: ='[52]Paid Visits'!L8 -> 668500 | H39: asc
B40: Social Media Paid Push | E40: 100000 | H40: asc
E41: =SUM(E35:E40) -> 3318500
B43: Misc. | G43: 1018510 | H43: MT Exp.
G44: 1274250 | H44: PAPs Exp.
B46: Grand Total | E46: =E41+E32+E26+E21+E13+E11+E6+E43 -> 98206300 | G46: =G41+G32+G26+G21+G13+G11+G6+G43+G44 -> 76583694 | H46: =G46-G9 -> 7583694
B48: Company wise Distribution
B49: AIL | E49: =E9 -> 81000000
B50: ASC | E50: =E46-E49 -> 17206300
E51: =E49+E50 -> 98206300
...

Sheet Sheet2
A1: FY 2021-22 (Rs.) | C1: FY 2022-23 (Rs.) | E1: FY 2023-24 (Rs.) | G1: FY 2024-25 (Rs.) | I1: FY 2025-26 (Rs.) | K1: FY 2026-27 (Rs.) | WZC1: Budget Utilization | WZD1: Remaining budget | WZE1: Utilization %
A2: Budget | B2: Actual | C2: Budget | D2: Actual | E2: Budget | F2: Actual | G2: Budget | H2: Actual | I2: Budget | J2: Actual | K2: Budget | L2: Actual
A3: 53 | B3: 78.16 | C3: 110 | D3: 25.85 | E3: 59.5 | F3: 64.64 | G3: 105.5 | H3: 58.66 | I3: 98 | J3: 78.16 | K3: 92 | N3: 2021 | O3: 26185857
N4: 2022 | O4: 78162905
N5: 2023 | O5: 25858204
N6: 2024 | O6: 64640138
N7: 2025 | O7: 58663408
N8: 2026 | O8: 78168862
B10: 2021-22 | C10: Budget | D10: 53
C11: Actual | D11: 78.16
B12: 2022-23 | C12: Budget | D12: 110
C13: Actual | D13: 25.85
B14: 2023-24 | C14: Budget | D14: 59.5
C15: Actual | D15: 64.64
B16: 2024-25 | C16: Budget | D16: 105.5
C17: Actual | D17: 58.66
B18: 2025-26 | C18: Budget | D18: 98
C19: Actual | D19: 78.16
B20: 2026-27 | C20: Budget | D20: 92
C21: Actual
C32: 2021-22 | D32: 2022-23 | E32: 2023-24 | F32: 2024-25 | G32: 2025-26 | H32: 2026-27
B33: Budget | C33: 74.31 | D33: 67.19 | E33: 65.47 | F33: 104.5 | G33: 90.58 | H33: 116
B34: Actual | C34: 78.16 | D34: 25.86 | E34: 64.64 | F34: 58.66 | G34: 93.72
B35: IT | H35: 48
